Workbook
Name Slicer_Region: #N/A
Name Slicer_Segment: #N/A
Name Slicer_Year: #N/A

Sheet Sheet2
A1: Row ID | B1: Order ID | C1: Year | D1: Order Date | E1: Ship Date | F1: Ship Mode | G1: Customer ID | H1: Customer Name | I1: Segment | J1: Country | K1: City | L1: State | M1: Postal Code | N1: Region | O1: Product ID | P1: Category | Q1: Sub-Category | R1: Product Name | S1: Sales | T1: Quantity | U1: Discount | V1: Profit
A2: 9972 | B2: CA-2012-103772 | C2: 2012 | D2: 41088 | E2: 41092 | F2: Standard Class | G2: MP-17470 | H2: Mark Packer | I2: Home Office | J2: United States | K2: Smyrna | L2: Georgia | M2: 30080 | N2: South | O2: OFF-AR-10000538 | P2: Office Supplies | Q2: Art | R2: Boston Model 1800 Electric Pencil Sharpener, Gray | S2: 140.75 | T2: 5 | U2: 0 | V2: 42.225
A3: 9971 | B3: CA-2012-103772 | C3: 2012 | D3: 41088 | E3: 41092 | F3: Standard Class | G3: MP-17470 | H3: Mark Packer | I3: Home Office | J3: United States | K3: Smyrna | L3: Georgia | M3: 30080 | N3: South | O3: OFF-BI-10002867 | P3: Office Supplies | Q3: Binders | R3: GBC Recycled Regency Composition Covers | S3: 119.56 | T3: 2 | U3: 0 | V3: 54.9976
A4: 3 | B4: CA-2013-138688 | C4: 2013 | D4: 41438 | E4: 41442 | F4: Second Class | G4: DV-13045 | H4: Darrin Van Huff | I4: Corporate | J4: United States | K4: Los Angeles | L4: California | M4: 90036 | N4: West | O4: OFF-LA-10000240 | P4: Office Supplies | Q4: Labels | R4: Self-Adhesive Address Labels for Typewriters by Universal | S4: 14.62 | T4: 2 | U4: 0 | V4: 6.8714
A5: 9952 | B5: CA-2014-121559 | C5: 2014 | D5: 41792 | E5: 41794 | F5: Second Class | G5: HW-14935 | H5: Helen Wasserman | I5: Corporate | J5: United States | K5: Indianapolis | L5: Indiana | M5: 46203 | N5: Central | O5: OFF-BI-10002072 | P5: Office Supplies | Q5: Binders | R5: Cardinal Slant-D Ring Binders | S5: 17.38 | T5: 2 | U5: 0 | V5: 8.69
A6: 9951 | B6: CA-2014-121559 | C6: 2014 | D6: 41792 | E6: 41794 | F6: Second Class | G6: HW-14935 | H6: Helen Wasserman | I6: Corporate | J6: United States | K6: Indianapolis | L6: Indiana | M6: 46203 | N6: Central | O6: TEC-AC-10001714 | P6: Technology | Q6: Accessories | R6: Logitech MX Performance Wireless Mouse | S6: 39.89 | T6: 1 | U6: 0 | V6: 14.7593
A7: 6 | B7: CA-2011-115812 | C7: 2011 | D7: 40703 | E7: 40708 | F7: Standard Class | G7: BH-11710 | H7: Brosina Hoffman | I7: Consumer | J7: United States | K7: Los Angeles | L7: California | M7: 90032 | N7: West | O7: FUR-FU-10001487 | P7: Furniture | Q7: Furnishings | R7: Eldon Expressions Wood and Plastic Desk Accessories, Cherry Wood | S7: 48.86 | T7: 7 | U7: 0 | V7: 14.1694
A8: 7 | B8: CA-2011-115812 | C8: 2011 | D8: 40703 | E8: 40708 | F8: Standard Class | G8: BH-11710 | H8: Brosina Hoffman | I8: Consumer | J8: United States | K8: Los Angeles | L8: California | M8: 90032 | N8: West | O8: OFF-AR-10002833 | P8: Office Supplies | Q8: Art | R8: Newell 322 | S8: 7.28 | T8: 4 | U8: 0 | V8: 1.9656
A9: 8 | B9: CA-2011-115812 | C9: 2011 | D9: 40703 | E9: 40708 | F9: Standard Class | G9: BH-11710 | H9: Brosina Hoffman | I9: Consumer | J9: United States | K9: Los Angeles | L9: California | M9: 90032 | N9: West | O9: TEC-PH-10002275 | P9: Technology | Q9: Phones | R9: Mitel 5320 IP Phone VoIP phone | S9: 907.152 | T9: 6 | U9: 0.2 | V9: 90.7152
A10: 9 | B10: CA-2011-115812 | C10: 2011 | D10: 40703 | E10: 40708 | F10: Standard Class | G10: BH-11710 | H10: Brosina Hoffman | I10: Consumer | J10: United States | K10: Los Angeles | L10: California | M10: 90032 | N10: West | O10: OFF-BI-10003910 | P10: Office Supplies | Q10: Binders | R10: DXL Angle-View Binders with Locking Rings by Samsill | S10: 18.504 | T10: 3 | U10: 0.2 | V10: 5.7825
A11: 10 | B11: CA-2011-115812 | C11: 2011 | D11: 40703 | E11: 40708 | F11: Standard Class | G11: BH-11710 | H11: Brosina Hoffman | I11: Consumer | J11: United States | K11: Los Angeles | L11: California | M11: 90032 | N11: West | O11: OFF-AP-10002892 | P11: Office Supplies | Q11: Appliances | R11: Belkin F5C206VTEL 6 Outlet Surge | S11: 114.9 | T11: 5 | U11: 0 | V11: 34.47
A12: 11 | B12: CA-2011-115812 | C12: 2011 | D12: 40703 | E12: 40708 | F12: Standard Class | G12: BH-11710 | H12: Brosina Hoffman | I12: Consumer | J12: United States | K12: Los Angeles | L12: California | M12: 90032 | N12: West | O12: FUR-TA-10001539 | P12: Furniture | Q12: Tables | R12: Chromcraft Rectangular Conference Tables | S12: 1706.184 | T12: 9 | U12: 0.2 | V12: 85.3092
A13: 12 | B13: CA-2011-115812 | C13: 2011 | D13: 40703 | E13: 40708 | F13: Standard Class | G13: BH-11710 | H13: Brosina Hoffman | I13: Consumer | J13: United States | K13: Los Angeles | L13: California | M13: 90032 | N13: West | O13: TEC-PH-10002033 | P13: Technology | Q13: Phones | R13: Konftel 250 Conference phone - Charcoal black | S13: 911.424 | T13: 4 | U13: 0.2 | V13: 68.3568
... A710: 719 | B710: CA-2011-104472 | C710: 2011 | D710: 40696 | E710: 40701 | F710: Standard Class | G710: CK-12325 | H710: Christine Kargatis | I710: Home Office | J710: United States | K710: Orem | L710: Utah | M710: 84057 | N710: West | O710: OFF-BI-10001658 | P710: Office Supplies | Q710: Binders | R710: GBC Standard Therm-A-Bind Covers | S710: 59.808 | T710: 3 | U710: 0.2 | V710: 19.4376

Sheet combo chart
A3: Row Labels | B3: Sum of Sales | C3: Sum of Profit
A4: Jan | B4: 6925.023 | C4: 1352.9421
A5: Feb | B5: 19437.495 | C5: 4745.0149
A6: Mar | B6: 25570.797 | C6: 4483.706
A7: Apr | B7: 19874.799 | C7: 1195.8169
A8: May | B8: 31699.545 | C8: 4856.0225
A9: Jun | B9: 25671.974 | C9: 3675.3093
A10: Jul | B10: 21346.232 | C10: 2907.9279
A11: Aug | B11: 12738.257 | C11: 952.9218
A12: Sep | B12: 42089.693 | C12: 8152.9909
A13: Oct | B13: 20973.185 | C13: 4621.2532
A14: Nov | B14: 43592.778 | C14: -974.0646
A15: Dec | B15: 44895.836 | C15: 7360.6714
A16: Grand Total | B16: 314815.61 | C16: 43330.512

Sheet Waterfall Chart
A3: Row Labels | B3: Sum of Profit | D3: Category | E3: Profit
A4: Office Supplies | B4: 20575.339 | D4: =A4 -> Office Supplies | E4: =GETPIVOTDATA("Profit",$A$3,"Category",A4) -> 20575.339
A5: Technology | B5: 16526.904 | D5: =A5 -> Technology | E5: =GETPIVOTDATA("Profit",$A$3,"Category",A5) -> 16526.904
A6: Furniture | B6: 6228.2691 | D6: =A6 -> Furniture | E6: =GETPIVOTDATA("Profit",$A$3,"Category",A6) -> 6228.2691
A7: Grand Total | B7: 43330.512 | D7: =A7 -> Grand Total | E7: 286397.02

Sheet Pie Chart
A3: Row Labels | B3: Sum of Sales
A4: Furniture | B4: 0.30847592
A5: Office Supplies | B5: 0.29692194
A6: Technology | B6: 0.39460214
A7: Grand Total | B7: 1

Sheet Map Chart
A3: Row Labels | B3: Sum of Sales | D3: State | E3: Sales
A4: Alabama | B4: 2673.01 | D4: =A4 -> Alabama | E4: =GETPIVOTDATA("Sales",$A$3,"State",A4) -> 2673.01
A5: Arizona | B5: 4348.9 | D5: =A5 -> Arizona | E5: =GETPIVOTDATA("Sales",$A$3,"State",A5) -> 4348.9
A6: Arkansas | B6: 2224.19 | D6: =A6 -> Arkansas | E6: =GETPIVOTDATA("Sales",$A$3,"State",A6) -> 2224.19
A7: California | B7: 86058.93 | D7: =A7 -> California | E7: =GETPIVOTDATA("Sales",$A$3,"State",A7) -> 86058.93
A8: Colorado | B8: 5564.389 | D8: =A8 -> Colorado | E8: =GETPIVOTDATA("Sales",$A$3,"State",A8) -> 5564.389
A9: Connecticut | B9: 2174.947 | D9: =A9 -> Connecticut | E9: =GETPIVOTDATA("Sales",$A$3,"State",A9) -> 2174.947
A10: Delaware | B10: 2371.77 | D10: =A10 -> Delaware | E10: =GETPIVOTDATA("Sales",$A$3,"State",A10) -> 2371.77
A11: District of Columbia | B11: 117.07 | D11: =A11 -> District of Columbia | E11: =GETPIVOTDATA("Sales",$A$3,"State",A11) -> 117.07
A12: Florida | B12: 7225.83 | D12: =A12 -> Florida | E12: =GETPIVOTDATA("Sales",$A$3,"State",A12) -> 7225.83
A13: Georgia | B13: 10975.28 | D13: =A13 -> Georgia | E13: =GETPIVOTDATA("Sales",$A$3,"State",A13) -> 10975.28
A14: Idaho | B14: 34.68 | D14: =A14 -> Idaho | E14: =GETPIVOTDATA("Sales",$A$3,"State",A14) -> 34.68
A15: Kentucky | B15: 4962.08 | D15: =A15 -> Kentucky | E15: =GETPIVOTDATA("Sales",$A$3,"State",A15) -> 4962.08
... A37: Grand Total | B37: 314815.61 | D37: =A37 -> Grand Total | E37: =GETPIVOTDATA("Sales",$A$3,"State",A37) -> #REF!
D38: =A38 -> 0 | E38: =GETPIVOTDATA("Sales",$A$3,"State",A38) -> #REF!
D39: =A39 -> 0 | E39: =GETPIVOTDATA("Sales",$A$3,"State",A39) -> #REF!
D40: =A40 -> 0 | E40: =GETPIVOTDATA("Sales",$A$3,"State",A40) -> #REF!
D41: =A41 -> 0 | E41: =GETPIVOTDATA("Sales",$A$3,"State",A41) -> #REF!
D42: =A42 -> 0 | E42: =GETPIVOTDATA("Sales",$A$3,"State",A42) -> #REF!
D43: =A43 -> 0 | E43: =GETPIVOTDATA("Sales",$A$3,"State",A43) -> #REF!
D44: =A44 -> 0 | E44: =GETPIVOTDATA("Sales",$A$3,"State",A44) -> #REF!
D45: =A45 -> 0 | E45: =GETPIVOTDATA("Sales",$A$3,"State",A45) -> #REF!
D46: =A46 -> 0 | E46: =GETPIVOTDATA("Sales",$A$3,"State",A46) -> #REF!
D47: =A47 -> 0 | E47: =GETPIVOTDATA("Sales",$A$3,"State",A47) -> #REF!
D48: =A48 -> 0 | E48: =GETPIVOTDATA("Sales",$A$3,"State",A48) -> #REF!
D49: =A49 -> 0 | E49: =GETPIVOTDATA("Sales",$A$3,"State",A49) -> #REF!
... D52: =A52 -> 0 | E52: =GETPIVOTDATA("Sales",$A$3,"State",A52) -> #REF!

Sheet Sheet7
A1: Row ID | B1: Order ID | C1: Year | D1: Order Date | E1: Ship Date | F1: Ship Mode | G1: Customer ID | H1: Customer Name | I1: Segment | J1: Country | K1: City | L1: State | M1: Postal Code | N1: Region | O1: Product ID | P1: Category | Q1: Sub-Category | R1: Product Name | S1: Sales | T1: Quantity | U1: Discount | V1: Profit
A2: 9948 | B2: CA-2014-121559 | C2: 2014 | D2: 41792 | E2: 41794 | F2: Second Class | G2: HW-14935 | H2: Helen Wasserman | I2: Corporate | J2: United States | K2: Indianapolis | L2: Indiana | M2: 46203 | N2: Central | O2: FUR-CH-10003746 | P2: Furniture | Q2: Chairs | R2: Hon 4070 Series Pagoda Round Back Stacking Chairs | S2: 1925.88 | T2: 6 | U2: 0 | V2: 539.2464
A3: 2 | B3: CA-2013-152156 | C3: 2013 | D3: 41587 | E3: 41590 | F3: Second Class | G3: CG-12520 | H3: Claire Gute | I3: Consumer | J3: United States | K3: Henderson | L3: Kentucky | M3: 42420 | N3: South | O3: FUR-CH-10000454 | P3: Furniture | Q3: Chairs | R3: Hon Deluxe Fabric Upholstered Stacking Chairs, Rounded Back | S3: 731.94 | T3: 3 | U3: 0 | V3: 219.582
A4: 9920 | B4: CA-2013-149272 | C4: 2013 | D4: 41349 | E4: 41353 | F4: Standard Class | G4: MY-18295 | H4: Muhammed Yedwab | I4: Corporate | J4: United States | K4: Bryan | L4: Texas | M4: 77803 | N4: Central | O4: FUR-CH-10000863 | P4: Furniture | Q4: Chairs | R4: Novimex Swivel Fabric Task Chair | S4: 528.43 | T4: 5 | U4: 0.3 | V4: -143.431
A5: 9913 | B5: CA-2012-132388 | C5: 2012 | D5: 41192 | E5: 41194 | F5: First Class | G5: KN-16390 | H5: Katherine Nockton | I5: Corporate | J5: United States | K5: Santa Barbara | L5: California | M5: 93101 | N5: West | O5: FUR-CH-10001714 | P5: Furniture | Q5: Chairs | R5: Global Leather & Oak Executive Chair, Burgundy | S5: 362.136 | T5: 3 | U5: 0.2 | V5: -54.3204
A6: 9908 | B6: US-2012-129007 | C6: 2012 | D6: 41165 | E6: 41167 | F6: First Class | G6: KD-16615 | H6: Ken Dana | I6: Corporate | J6: United States | K6: Anaheim | L6: California | M6: 92804 | N6: West | O6: FUR-CH-10000155 | P6: Furniture | Q6: Chairs | R6: Global Comet Stacking Armless Chair | S6: 717.72 | T6: 3 | U6: 0.2 | V6: 71.772
A7: 9894 | B7: US-2013-115441 | C7: 2013 | D7: 41481 | E7: 41484 | F7: Second Class | G7: SH-19975 | H7: Sally Hughsby | I7: Corporate | J7: United States | K7: Milwaukee | L7: Wisconsin | M7: 53209 | N7: Central | O7: FUR-CH-10004626 | P7: Furniture | Q7: Chairs | R7: Office Star Flex Back Scooter Chair with Aluminum Finish Frame | S7: 403.56 | T7: 4 | U7: 0 | V7: 96.8544
A8: 9880 | B8: CA-2013-122581 | C8: 2013 | D8: 41508 | E8: 41512 | F8: Standard Class | G8: JK-15370 | H8: Jay Kimmel | I8: Consumer | J8: United States | K8: New York City | L8: New York | M8: 10035 | N8: East | O8: FUR-CH-10002961 | P8: Furniture | Q8: Chairs | R8: Leather Task Chair, Black | S8: 573.174 | T8: 7 | U8: 0.1 | V8: 63.686
A9: 9843 | B9: US-2013-125402 | C9: 2013 | D9: 41543 | E9: 41549 | F9: Standard Class | G9: DL-12865 | H9: Dan Lawera | I9: Consumer | J9: United States | K9: Long Beach | L9: California | M9: 90805 | N9: West | O9: FUR-CH-10000665 | P9: Furniture | Q9: Chairs | R9: Global Airflow Leather Mesh Back Chair, Black | S9: 483.136 | T9: 4 | U9: 0.2 | V9: 60.392
A10: 9830 | B10: US-2014-152842 | C10: 2014 | D10: 41837 | E10: 41844 | F10: Standard Class | G10: NF-18385 | H10: Natalie Fritzler | I10: Consumer | J10: United States | K10: Charlotte | L10: North Carolina | M10: 28205 | N10: South | O10: FUR-CH-10004218 | P10: Furniture | Q10: Chairs | R10: Global Fabric Manager's Chair, Dark Gray | S10: 242.352 | T10: 3 | U10: 0.2 | V10: 15.147
A11: 9827 | B11: US-2011-164406 | C11: 2011 | D11: 40770 | E11: 40774 | F11: Standard Class | G11: BD-11605 | H11: Brian Dahlen | I11: Consumer | J11: United States | K11: San Francisco | L11: California | M11: 94122 | N11: West | O11: FUR-CH-10003833 | P11: Furniture | Q11: Chairs | R11: Novimex Fabric Task Chair | S11: 195.136 | T11: 4 | U11: 0.2 | V11: -12.196
A12: 9808 | B12: CA-2014-107209 | C12: 2014 | D12: 41848 | E12: 41853 | F12: Second Class | G12: JW-15955 | H12: Joni Wasserman | I12: Consumer | J12: United States | K12: Raleigh | L12: North Carolina | M12: 27604 | N12: South | O12: FUR-CH-10001146 | P12: Furniture | Q12: Chairs | R12: Global Value Mid-Back Manager's Chair, Gray | S12: 194.848 | T12: 4 | U12: 0.2 | V12: 12.178
A13: 9793 | B13: CA-2011-127166 | C13: 2011 | D13: 40684 | E13: 40686 | F13: Second Class | G13: KH-16360 | H13: Katherine Hughes | I13: Consumer | J13: United States | K13: Houston | L13: Texas | M13: 77070 | N13: Central | O13: FUR-CH-10003396 | P13: Furniture | Q13: Chairs | R13: Global Deluxe Steno Chair | S13: 107.772 | T13: 2 | U13: 0.3 | V13: -29.2524
... A323: 5278 | B323: CA-2011-113859 | C323: 2011 | D323: 40799 | E323: 40803 | F323: Standard Class | G323: BC-11125 | H323: Becky Castell | I323: Home Office | J323: United States | K323: Odessa | L323: Texas | M323: 79762 | N323: Central | O323: FUR-CH-10004698 | P323: Furniture | Q323: Chairs | R323: Padded Folding Chairs, Black, 4/Carton | S323: 340.116 | T323: 6 | U323: 0.3 | V323: -9.7176
A324: 5275 | B324: CA-2012-162887 | C324: 2012 | D324: 41220 | E324: 41222 | F324: Second Class | G324: SV-20785 | H324: Stewart Visinsky | I324: Consumer | J324: United States | K324: Burlington | L324: Vermont | M324: 05408 | N324: East | O324: FUR-CH-10000595 | P324: Furniture | Q324: Chairs | R324: Safco Contoured Stacking Chairs | S324: 715.2 | T324: 3 | U324: 0 | V324: 178.8
A325: 5255 | B325: CA-2012-125185 | C325: 2012 | D325: 40973 | E325: 40975 | F325: Second Class | G325: AH-10195 | H325: Alan Haines | I325: Corporate | J325: United States | K325: Bethlehem | L325: Pennsylvania | M325: 18018 | N325: East | O325: FUR-CH-10002647 | P325: Furniture | Q325: Chairs | R325: Situations Contoured Folding Chairs, 4/Set | S325: 99.372 | T325: 2 | U325: 0.3 | V325: -7.098
A326: 5234 | B326: CA-2011-115084 | C326: 2011 | D326: 40834 | E326: 40838 | F326: Standard Class | G326: LS-17200 | H326: Luke Schmidt | I326: Corporate | J326: United States | K326: Texarkana | L326: Arkansas | M326: 71854 | N326: South | O326: FUR-CH-10004626 | P326: Furniture | Q326: Chairs | R326: Office Star Flex Back Scooter Chair with Aluminum Finish Frame | S326: 605.34 | T326: 6 | U326: 0 | V326: 145.2816
A327: 5220 | B327: CA-2014-145653 | C327: 2014 | D327: 41884 | E327: 41884 | F327: Same Day | G327: CA-12775 | H327: Cynthia Arntzen | I327: Consumer | J327: United States | K327: Detroit | L327: Michigan | M327: 48205 | N327: Central | O327: FUR-CH-10004875 | P327: Furniture | Q327: Chairs | R327: Harbour Creations 67200 Series Stacking Chairs | S327: 498.26 | T327: 7 | U327: 0 | V327: 134.5302
A328: 5189 | B328: CA-2012-115567 | C328: 2012 | D328: 41165 | E328: 41170 | F328: Standard Class | G328: ZC-21910 | H328: Zuschuss Carroll | I328: Consumer | J328: United States | K328: Columbus | L328: Indiana | M328: 47201 | N328: Central | O328: FUR-CH-10000015 | P328: Furniture | Q328: Chairs | R328: Hon Multipurpose Stacking Arm Chairs | S328: 1516.2 | T328: 7 | U328: 0 | V328: 394.212
A329: 5171 | B329: CA-2013-122903 | C329: 2013 | D329: 41422 | E329: 41424 | F329: Second Class | G329: LA-16780 | H329: Laura Armstrong | I329: Corporate | J329: United States | K329: Detroit | L329: Michigan | M329: 48205 | N329: Central | O329: FUR-CH-10002024 | P329: Furniture | Q329: Chairs | R329: HON 5400 Series Task Chairs for Big and Tall | S329: 3504.9 | T329: 5 | U329: 0 | V329: 700.98
A330: 329 | B330: US-2013-141544 | C330: 2013 | D330: 41517 | E330: 41519 | F330: First Class | G330: PO-18850 | H330: Patrick O'Brill | I330: Consumer | J330: United States | K330: Philadelphia | L330: Pennsylvania | M330: 19143 | N330: East | O330: FUR-CH-10003312 | P330: Furniture | Q330: Chairs | R330: Hon 2090 “Pillow Soft” Series Mid Back Swivel/Tilt Chairs | S330: 786.744 | T330: 4 | U330: 0.3 | V330: -258.5016
A331: 5168 | B331: CA-2011-121006 | C331: 2011 | D331: 40857 | E331: 40863 | F331: Standard Class | G331: SC-20020 | H331: Sam Craven | I331: Consumer | J331: United States | K331: Midland | L331: Michigan | M331: 48640 | N331: Central | O331: FUR-CH-10004997 | P331: Furniture | Q331: Chairs | R331: Hon Every-Day Series Multi-Task Chairs | S331: 563.94 | T331: 3 | U331: 0 | V331: 112.788
A332: 5164 | B332: CA-2012-161627 | C332: 2012 | D332: 41096 | E332: 41101 | F332: Standard Class | G332: SJ-20215 | H332: Sarah Jordon | I332: Consumer | J332: United States | K332: Pasadena | L332: California | M332: 91104 | N332: West | O332: FUR-CH-10003968 | P332: Furniture | Q332: Chairs | R332: Novimex Turbo Task Chair | S332: 170.352 | T332: 3 | U332: 0.2 | V332: -17.0352
A333: 5163 | B333: CA-2013-115378 | C333: 2013 | D333: 41597 | E333: 41602 | F333: Second Class | G333: AJ-10945 | H333: Ashley Jarboe | I333: Consumer | J333: United States | K333: Taylor | L333: Michigan | M333: 48180 | N333: Central | O333: FUR-CH-10000863 | P333: Furniture | Q333: Chairs | R333: Novimex Swivel Fabric Task Chair | S333: 301.96 | T333: 2 | U333: 0 | V333: 33.2156
A334: 5158 | B334: CA-2014-163006 | C334: 2014 | D334: 41821 | E334: 41825 | F334: Second Class | G334: GH-14410 | H334: Gary Hansen | I334: Home Office | J334: United States | K334: Chicago | L334: Illinois | M334: 60653 | N334: Central | O334: FUR-CH-10000229 | P334: Furniture | Q334: Chairs | R334: Global Enterprise Series Seating High-Back Swivel/Tilt Chairs | S334: 569.058 | T334: 3 | U334: 0.3 | V334: -178.8468
A335: 5149 | B335: CA-2014-128734 | C335: 2014 | D335: 41998 | E335: 42005 | F335: Standard Class | G335: JL-15175 | H335: James Lanier | I335: Home Office | J335: United States | K335: Chandler | L335: Arizona | M335: 85224 | N335: West | O335: FUR-CH-10001394 | P335: Furniture | Q335: Chairs | R335: Global Leather Executive Chair | S335: 842.376 | T335: 3 | U335: 0.2 | V335: 105.297
A336: 5142 | B336: CA-2013-111213 | C336: 2013 | D336: 41366 | E336: 41370 | F336: Standard Class | G336: FP-14320 | H336: Frank Preis | I336: Consumer | J336: United States | K336: New York City | L336: New York | M336: 10009 | N336: East | O336: FUR-CH-10000454 | P336: Furniture | Q336: Chairs | R336: Hon Deluxe Fabric Upholstered Stacking Chairs, Rounded Back | S336: 1317.492 | T336: 6 | U336: 0.1 | V336: 292.776
... A618: 623 | B618: CA-2012-138009 | C618: 2012 | D618: 41242 | E618: 41246 | F618: Standard Class | G618: SF-20965 | H618: Sylvia Foulston | I618: Corporate | J618: United States | K618: Dearborn | L618: Michigan | M618: 48126 | N618: Central | O618: FUR-CH-10004853 | P618: Furniture | Q618: Chairs | R618: Global Manager's Adjustable Task Chair, Storm | S618: 301.96 | T618: 2 | U618: 0 | V618: 87.5684

Sheet Top 5
A3: Row Labels | B3: Sum of Sales
A4: Binders | B4: 27917.634
A5: Storage | B5: 30563.576
A6: Machines | B6: 36227.711
A7: Chairs | B7: 40110.463
A8: Phones | B8: 41165.652
A9: Grand Total | B9: 175985.04

Sheet KPI
A3: Row Labels | B3: Sum of Sales | D3: Row Labels | E3: Sum of Profit | G3: Row Labels | H3: Sum of Quantity | J3: Row Labels | K3: Count of Order ID | M3: Row Labels | N3: Sum of Profit Margin
A4: Jan | B4: 6925.023 | D4: Jan | E4: 1352.9421 | G4: Jan | H4: 191 | J4: Jan | K4: 48 | M4: Jan | N4: 0.19537005
A5: Feb | B5: 19437.495 | D5: Feb | E5: 4745.0149 | G5: Feb | H5: 184 | J5: Feb | K5: 53 | M5: Feb | N5: 0.24411658
A6: Mar | B6: 25570.797 | D6: Mar | E6: 4483.706 | G6: Mar | H6: 286 | J6: Mar | K6: 78 | M6: Mar | N6: 0.17534479
A7: Apr | B7: 19874.799 | D7: Apr | E7: 1195.8169 | G7: Apr | H7: 435 | J7: Apr | K7: 116 | M7: Apr | N7: 0.060167497
A8: May | B8: 31699.545 | D8: May | E8: 4856.0225 | G8: May | H8: 462 | J8: May | K8: 124 | M8: May | N8: 0.15318903
A9: Jun | B9: 25671.974 | D9: Jun | E9: 3675.3093 | G9: Jun | H9: 433 | J9: Jun | K9: 117 | M9: Jun | N9: 0.14316427
A10: Jul | B10: 21346.232 | D10: Jul | E10: 2907.9279 | G10: Jul | H10: 373 | J10: Jul | K10: 97 | M10: Jul | N10: 0.13622675
A11: Aug | B11: 12738.257 | D11: Aug | E11: 952.9218 | G11: Aug | H11: 325 | J11: Aug | K11: 79 | M11: Aug | N11: 0.074807864
A12: Sep | B12: 42089.693 | D12: Sep | E12: 8152.9909 | G12: Sep | H12: 674 | J12: Sep | K12: 193 | M12: Sep | N12: 0.19370516
A13: Oct | B13: 20973.185 | D13: Oct | E13: 4621.2532 | G13: Oct | H13: 360 | J13: Oct | K13: 91 | M13: Oct | N13: 0.22034103
A14: Nov | B14: 43592.778 | D14: Nov | E14: -974.0646 | G14: Nov | H14: 733 | J14: Nov | K14: 197 | M14: Nov | N14: -0.022344632
A15: Dec | B15: 44895.836 | D15: Dec | E15: 7360.6714 | G15: Dec | H15: 734 | J15: Dec | K15: 190 | M15: Dec | N15: 0.16394998
A16: Grand Total | B16: 314815.61 | D16: Grand Total | E16: 43330.512 | G16: Grand Total | H16: 5190 | J16: Grand Total | K16: 1383 | M16: Grand Total | N16: 0.13763775
B17: =GETPIVOTDATA("Sales",$A$3) -> 314815.61 | E17: =GETPIVOTDATA("Profit",$D$3) -> 43330.512 | H17: =GETPIVOTDATA("Quantity",$G$3) -> 5190 | K17: =GETPIVOTDATA("Order ID",$J$3) -> 1383 | N17: =GETPIVOTDATA("Profit Margin",$M$3) -> 0.13763775

Sheet KPI YOY
A3: Row Labels | B3: Sum of Sales | C3: Sum of Profit | D3: Sum of Quantity | E3: Count of Order ID | F3: Sum of Profit Margin
A4: 2011 | B4: 271876.4 | C4: 34870.212 | D4: 3912 | E4: 1031 | F4: 0.12825759
A5: 2012 | B5: 267980.7 | C5: 35204.652 | D5: 4274 | E5: 1133 | F5: 0.1313701
A6: 2013 | B6: 314815.61 | C6: 43330.512 | D6: 5190 | E6: 1383 | F6: 0.13763775
A7: 2014 | B7: 393137.7 | C7: 60010.05 | D7: 6713 | E7: 1777 | F7: 0.15264385
H8: =(GETPIVOTDATA("Sum of Sales",$A$3,"Years",2014)/GETPIVOTDATA("Sum of Sales",$A$3,"Years",2013))-1 -> 0.24878716 | I8: =(GETPIVOTDATA("Sum of Profit",$A$3,"Years",2014)/GETPIVOTDATA("Sum of Profit",$A$3,"Years",2013))-1 -> 0.38493748 | J8: =(GETPIVOTDATA("Sum of Quantity",$A$3,"Years",2014)/GETPIVOTDATA("Sum of Quantity",$A$3,"Years",2013))-1 -> 0.29344894 | K8: =(GETPIVOTDATA("Count of Order ID",$A$3,"Years",2014)/GETPIVOTDATA("Count of Order ID",$A$3,"Years",2013))-1 -> 0.28488792 | L8: =(GETPIVOTDATA("Sum of Profit Margin",$A$3,"Years",2014)/GETPIVOTDATA("Sum of Profit Margin",$A$3,"Years",2013))-1 -> 0.10902604

Sheet Dashboard

Sheet Data
A1: Row ID | B1: Order ID | C1: Year | D1: Order Date | E1: Ship Date | F1: Ship Mode | G1: Customer ID | H1: Customer Name | I1: Segment | J1: Country | K1: City | L1: State | M1: Postal Code | N1: Region | O1: Product ID | P1: Category | Q1: Sub-Category | R1: Product Name | S1: Sales | T1: Quantity | U1: Discount | V1: Profit
A2: 1 | B2: CA-2013-152156 | C2: =YEAR(Data!$D2) -> 2013 | D2: 41587 | E2: 41590 | F2: Second Class | G2: CG-12520 | H2: Claire Gute | I2: Consumer | J2: United States | K2: Henderson | L2: Kentucky | M2: 42420 | N2: South | O2: FUR-BO-10001798 | P2: Furniture | Q2: Bookcases | R2: Bush Somerset Collection Bookcase | S2: 261.96 | T2: 2 | U2: 0 | V2: 41.9136
A3: 2 | B3: CA-2013-152156 | C3: =YEAR(Data!$D3) -> 2013 | D3: 41587 | E3: 41590 | F3: Second Class | G3: CG-12520 | H3: Claire Gute | I3: Consumer | J3: United States | K3: Henderson | L3: Kentucky | M3: 42420 | N3: South | O3: FUR-CH-10000454 | P3: Furniture | Q3: Chairs | R3: Hon Deluxe Fabric Upholstered Stacking Chairs, Rounded Back | S3: 731.94 | T3: 3 | U3: 0 | V3: 219.582
A4: 3 | B4: CA-2013-138688 | C4: =YEAR(Data!$D4) -> 2013 | D4: 41438 | E4: 41442 | F4: Second Class | G4: DV-13045 | H4: Darrin Van Huff | I4: Corporate | J4: United States | K4: Los Angeles | L4: California | M4: 90036 | N4: West | O4: OFF-LA-10000240 | P4: Office Supplies | Q4: Labels | R4: Self-Adhesive Address Labels for Typewriters by Universal | S4: 14.62 | T4: 2 | U4: 0 | V4: 6.8714
A5: 4 | B5: US-2012-108966 | C5: =YEAR(Data!$D5) -> 2012 | D5: 41193 | E5: 41200 | F5: Standard Class | G5: SO-20335 | H5: Sean O'Donnell | I5: Consumer | J5: United States | K5: Fort Lauderdale | L5: Florida | M5: 33311 | N5: South | O5: FUR-TA-10000577 | P5: Furniture | Q5: Tables | R5: Bretford CR4500 Series Slim Rectangular Table | S5: 957.5775 | T5: 5 | U5: 0.45 | V5: -383.031
A6: 5 | B6: US-2012-108966 | C6: =YEAR(Data!$D6) -> 2012 | D6: 41193 | E6: 41200 | F6: Standard Class | G6: SO-20335 | H6: Sean O'Donnell | I6: Consumer | J6: United States | K6: Fort Lauderdale | L6: Florida | M6: 33311 | N6: South | O6: OFF-ST-10000760 | P6: Office Supplies | Q6: Storage | R6: Eldon Fold 'N Roll Cart System | S6: 22.368 | T6: 2 | U6: 0.2 | V6: 2.5164
A7: 6 | B7: CA-2011-115812 | C7: =YEAR(Data!$D7) -> 2011 | D7: 40703 | E7: 40708 | F7: Standard Class | G7: BH-11710 | H7: Brosina Hoffman | I7: Consumer | J7: United States | K7: Los Angeles | L7: California | M7: 90032 | N7: West | O7: FUR-FU-10001487 | P7: Furniture | Q7: Furnishings | R7: Eldon Expressions Wood and Plastic Desk Accessories, Cherry Wood | S7: 48.86 | T7: 7 | U7: 0 | V7: 14.1694
A8: 7 | B8: CA-2011-115812 | C8: =YEAR(Data!$D8) -> 2011 | D8: 40703 | E8: 40708 | F8: Standard Class | G8: BH-11710 | H8: Brosina Hoffman | I8: Consumer | J8: United States | K8: Los Angeles | L8: California | M8: 90032 | N8: West | O8: OFF-AR-10002833 | P8: Office Supplies | Q8: Art | R8: Newell 322 | S8: 7.28 | T8: 4 | U8: 0 | V8: 1.9656
A9: 8 | B9: CA-2011-115812 | C9: =YEAR(Data!$D9) -> 2011 | D9: 40703 | E9: 40708 | F9: Standard Class | G9: BH-11710 | H9: Brosina Hoffman | I9: Consumer | J9: United States | K9: Los Angeles | L9: California | M9: 90032 | N9: West | O9: TEC-PH-10002275 | P9: Technology | Q9: Phones | R9: Mitel 5320 IP Phone VoIP phone | S9: 907.152 | T9: 6 | U9: 0.2 | V9: 90.7152
A10: 9 | B10: CA-2011-115812 | C10: =YEAR(Data!$D10) -> 2011 | D10: 40703 | E10: 40708 | F10: Standard Class | G10: BH-11710 | H10: Brosina Hoffman | I10: Consumer | J10: United States | K10: Los Angeles | L10: California | M10: 90032 | N10: West | O10: OFF-BI-10003910 | P10: Office Supplies | Q10: Binders | R10: DXL Angle-View Binders with Locking Rings by Samsill | S10: 18.504 | T10: 3 | U10: 0.2 | V10: 5.7825
A11: 10 | B11: CA-2011-115812 | C11: =YEAR(Data!$D11) -> 2011 | D11: 40703 | E11: 40708 | F11: Standard Class | G11: BH-11710 | H11: Brosina Hoffman | I11: Consumer | J11: United States | K11: Los Angeles | L11: California | M11: 90032 | N11: West | O11: OFF-AP-10002892 | P11: Office Supplies | Q11: Appliances | R11: Belkin F5C206VTEL 6 Outlet Surge | S11: 114.9 | T11: 5 | U11: 0 | V11: 34.47
A12: 11 | B12: CA-2011-115812 | C12: =YEAR(Data!$D12) -> 2011 | D12: 40703 | E12: 40708 | F12: Standard Class | G12: BH-11710 | H12: Brosina Hoffman | I12: Consumer | J12: United States | K12: Los Angeles | L12: California | M12: 90032 | N12: West | O12: FUR-TA-10001539 | P12: Furniture | Q12: Tables | R12: Chromcraft Rectangular Conference Tables | S12: 1706.184 | T12: 9 | U12: 0.2 | V12: 85.3092
A13: 12 | B13: CA-2011-115812 | C13: =YEAR(Data!$D13) -> 2011 | D13: 40703 | E13: 40708 | F13: Standard Class | G13: BH-11710 | H13: Brosina Hoffman | I13: Consumer | J13: United States | K13: Los Angeles | L13: California | M13: 90032 | N13: West | O13: TEC-PH-10002033 | P13: Technology | Q13: Phones | R13: Konftel 250 Conference phone - Charcoal black | S13: 911.424 | T13: 4 | U13: 0.2 | V13: 68.3568
... A2235: 2234 | B2235: CA-2012-123232 | C2235: =YEAR(Data!$D2235) -> 2012 | D2235: 41257 | E2235: 41259 | F2235: Second Class | G2235: DJ-13630 | H2235: Doug Jacobs | I2235: Consumer | J2235: United States | K2235: Portland | L2235: Oregon | M2235: 97206 | N2235: West | O2235: TEC-PH-10001051 | P2235: Technology | Q2235: Phones | R2235: HTC One | S2235: 319.968 | T2235: 4 | U2235: 0.2 | V2235: 35.9964
A2236: 2235 | B2236: CA-2014-104066 | C2236: =YEAR(Data!$D2236) -> 2014 | D2236: 41979 | E2236: 41984 | F2236: Standard Class | G2236: QJ-19255 | H2236: Quincy Jones | I2236: Corporate | J2236: United States | K2236: Burlington | L2236: Vermont | M2236: 05408 | N2236: East | O2236: TEC-AC-10001013 | P2236: Technology | Q2236: Accessories | R2236: Logitech ClearChat Comfort/USB Headset H390 | S2236: 205.03 | T2236: 7 | U2236: 0 | V2236: 67.6599
A2237: 2236 | B2237: CA-2012-145849 | C2237: =YEAR(Data!$D2237) -> 2012 | D2237: 41167 | E2237: 41169 | F2237: Second Class | G2237: CT-11995 | H2237: Carol Triggs | I2237: Consumer | J2237: United States | K2237: Indianapolis | L2237: Indiana | M2237: 46203 | N2237: Central | O2237: OFF-ST-10000025 | P2237: Office Supplies | Q2237: Storage | R2237: Fellowes Stor/Drawer Steel Plus Storage Drawers | S2237: 190.86 | T2237: 2 | U2237: 0 | V2237: 11.4516
A2238: 2237 | B2238: CA-2012-145849 | C2238: =YEAR(Data!$D2238) -> 2012 | D2238: 41167 | E2238: 41169 | F2238: Second Class | G2238: CT-11995 | H2238: Carol Triggs | I2238: Consumer | J2238: United States | K2238: Indianapolis | L2238: Indiana | M2238: 46203 | N2238: Central | O2238: OFF-AR-10000817 | P2238: Office Supplies | Q2238: Art | R2238: Manco Dry-Lighter Erasable Highlighter | S2238: 24.32 | T2238: 8 | U2238: 0 | V2238: 8.2688
A2239: 2238 | B2239: CA-2013-122322 | C2239: =YEAR(Data!$D2239) -> 2013 | D2239: 41471 | E2239: 41477 | F2239: Standard Class | G2239: RH-19510 | H2239: Rick Huthwaite | I2239: Home Office | J2239: United States | K2239: Provo | L2239: Utah | M2239: 84604 | N2239: West | O2239: OFF-SU-10000952 | P2239: Office Supplies | Q2239: Supplies | R2239: Fiskars Home & Office Scissors | S2239: 44.4 | T2239: 5 | U2239: 0 | V2239: 12.432
A2240: 2239 | B2240: CA-2014-166849 | C2240: =YEAR(Data!$D2240) -> 2014 | D2240: 41750 | E2240: 41756 | F2240: Standard Class | G2240: SJ-20125 | H2240: Sanjit Jacobs | I2240: Home Office | J2240: United States | K2240: Chicago | L2240: Illinois | M2240: 60610 | N2240: Central | O2240: FUR-FU-10004597 | P2240: Furniture | Q2240: Furnishings | R2240: Eldon Cleatmat Chair Mats for Medium Pile Carpets | S2240: 44.4 | T2240: 2 | U2240: 0.6 | V2240: -52.17
A2241: 2240 | B2241: CA-2013-146633 | C2241: =YEAR(Data!$D2241) -> 2013 | D2241: 41594 | E2241: 41596 | F2241: Second Class | G2241: TG-21310 | H2241: Toby Gnade | I2241: Consumer | J2241: United States | K2241: Los Angeles | L2241: California | M2241: 90049 | N2241: West | O2241: OFF-BI-10003527 | P2241: Office Supplies | Q2241: Binders | R2241: Fellowes PB500 Electric Punch Plastic Comb Binding Machine with Manual Bind | S2241: 1016.792 | T2241: 1 | U2241: 0.2 | V2241: 381.297
A2242: 2241 | B2242: CA-2013-146633 | C2242: =YEAR(Data!$D2242) -> 2013 | D2242: 41594 | E2242: 41596 | F2242: Second Class | G2242: TG-21310 | H2242: Toby Gnade | I2242: Consumer | J2242: United States | K2242: Los Angeles | L2242: California | M2242: 90049 | N2242: West | O2242: OFF-BI-10002982 | P2242: Office Supplies | Q2242: Binders | R2242: Avery Self-Adhesive Photo Pockets for Polaroid Photos | S2242: 38.136 | T2242: 7 | U2242: 0.2 | V2242: 13.3476
A2243: 2242 | B2243: US-2013-126893 | C2243: =YEAR(Data!$D2243) -> 2013 | D2243: 41605 | E2243: 41610 | F2243: Standard Class | G2243: CT-11995 | H2243: Carol Triggs | I2243: Consumer | J2243: United States | K2243: Philadelphia | L2243: Pennsylvania | M2243: 19134 | N2243: East | O2243: TEC-PH-10004165 | P2243: Technology | Q2243: Phones | R2243: Mitel MiVoice 5330e IP Phone | S2243: 494.982 | T2243: 3 | U2243: 0.4 | V2243: -115.4958
A2244: 2243 | B2244: CA-2014-103380 | C2244: =YEAR(Data!$D2244) -> 2014 | D2244: 41965 | E2244: 41969 | F2244: Standard Class | G2244: BF-11005 | H2244: Barry Franz | I2244: Home Office | J2244: United States | K2244: Pasadena | L2244: California | M2244: 91104 | N2244: West | O2244: OFF-ST-10003442 | P2244: Office Supplies | Q2244: Storage | R2244: Eldon Portable Mobile Manager | S2244: 56.56 | T2244: 2 | U2244: 0 | V2244: 15.2712
A2245: 2244 | B2245: CA-2014-103380 | C2245: =YEAR(Data!$D2245) -> 2014 | D2245: 41965 | E2245: 41969 | F2245: Standard Class | G2245: BF-11005 | H2245: Barry Franz | I2245: Home Office | J2245: United States | K2245: Pasadena | L2245: California | M2245: 91104 | N2245: West | O2245: OFF-AR-10003856 | P2245: Office Supplies | Q2245: Art | R2245: Newell 344 | S2245: 5.56 | T2245: 2 | U2245: 0 | V2245: 1.4456
A2246: 2245 | B2246: CA-2014-103380 | C2246: =YEAR(Data!$D2246) -> 2014 | D2246: 41965 | E2246: 41969 | F2246: Standard Class | G2246: BF-11005 | H2246: Barry Franz | I2246: Home Office | J2246: United States | K2246: Pasadena | L2246: California | M2246: 91104 | N2246: West | O2246: OFF-FA-10004248 | P2246: Office Supplies | Q2246: Fasteners | R2246: Advantus T-Pin Paper Clips | S2246: 9.02 | T2246: 2 | U2246: 0 | V2246: 3.5178
A2247: 2246 | B2247: CA-2014-103380 | C2247: =YEAR(Data!$D2247) -> 2014 | D2247: 41965 | E2247: 41969 | F2247: Standard Class | G2247: BF-11005 | H2247: Barry Franz | I2247: Home Office | J2247: United States | K2247: Pasadena | L2247: California | M2247: 91104 | N2247: West | O2247: OFF-AP-10001492 | P2247: Office Supplies | Q2247: Appliances | R2247: Acco Six-Outlet Power Strip, 4' Cord Length | S2247: 8.62 | T2247: 1 | U2247: 0 | V2247: 2.2412
A2248: 2247 | B2248: CA-2014-103380 | C2248: =YEAR(Data!$D2248) -> 2014 | D2248: 41965 | E2248: 41969 | F2248: Standard Class | G2248: BF-11005 | H2248: Barry Franz | I2248: Home Office | J2248: United States | K2248: Pasadena | L2248: California | M2248: 91104 | N2248: West | O2248: TEC-PH-10004165 | P2248: Technology | Q2248: Phones | R2248: Mitel MiVoice 5330e IP Phone | S2248: 659.976 | T2248: 3 | U2248: 0.2 | V2248: 49.4982
... A5275: 5274 | B5275: US-2013-158309 | C5275: =YEAR(Data!$D5275) -> 2013 | D5275: 41605 | E5275: 41608 | F5275: First Class | G5275: PA-19060 | H5275: Pete Armstrong | I5275: Home Office | J5275: United States | K5275: Miami | L5275: Florida | M5275: 33142 | N5275: South | O5275: OFF-BI-10000145 | P5275: Office Supplies | Q5275: Binders | R5275: Zipper Ring Binder Pockets | S5275: 3.744 | T5275: 4 | U5275: 0.7 | V5275: -2.6208
A5276: 5275 | B5276: CA-2012-162887 | C5276: =YEAR(Data!$D5276) -> 2012 | D5276: 41220 | E5276: 41222 | F5276: Second Class | G5276: SV-20785 | H5276: Stewart Visinsky | I5276: Consumer | J5276: United States | K5276: Burlington | L5276: Vermont | M5276: 05408 | N5276: East | O5276: FUR-CH-10000595 | P5276: Furniture | Q5276: Chairs | R5276: Safco Contoured Stacking Chairs | S5276: 715.2 | T5276: 3 | U5276: 0 | V5276: 178.8
A5277: 5276 | B5277: CA-2014-147333 | C5277: =YEAR(Data!$D5277) -> 2014 | D5277: 41988 | E5277: 41994 | F5277: Standard Class | G5277: KL-16555 | H5277: Kelly Lampkin | I5277: Corporate | J5277: United States | K5277: Fayetteville | L5277: Arkansas | M5277: 72701 | N5277: South | O5277: TEC-AC-10004469 | P5277: Technology | Q5277: Accessories | R5277: Microsoft Sculpt Comfort Mouse | S5277: 159.8 | T5277: 4 | U5277: 0 | V5277: 70.312
A5278: 5277 | B5278: CA-2014-147333 | C5278: =YEAR(Data!$D5278) -> 2014 | D5278: 41988 | E5278: 41994 | F5278: Standard Class | G5278: KL-16555 | H5278: Kelly Lampkin | I5278: Corporate | J5278: United States | K5278: Fayetteville | L5278: Arkansas | M5278: 72701 | N5278: South | O5278: TEC-AC-10003038 | P5278: Technology | Q5278: Accessories | R5278: Kingston Digital DataTraveler 16GB USB 2.0 | S5278: 44.75 | T5278: 5 | U5278: 0 | V5278: 8.5025
A5279: 5278 | B5279: CA-2011-113859 | C5279: =YEAR(Data!$D5279) -> 2011 | D5279: 40799 | E5279: 40803 | F5279: Standard Class | G5279: BC-11125 | H5279: Becky Castell | I5279: Home Office | J5279: United States | K5279: Odessa | L5279: Texas | M5279: 79762 | N5279: Central | O5279: FUR-CH-10004698 | P5279: Furniture | Q5279: Chairs | R5279: Padded Folding Chairs, Black, 4/Carton | S5279: 340.116 | T5279: 6 | U5279: 0.3 | V5279: -9.7176
A5280: 5279 | B5280: CA-2011-159681 | C5280: =YEAR(Data!$D5280) -> 2011 | D5280: 40884 | E5280: 40890 | F5280: Standard Class | G5280: PO-18850 | H5280: Patrick O'Brill | I5280: Consumer | J5280: United States | K5280: Virginia Beach | L5280: Virginia | M5280: 23464 | N5280: South | O5280: OFF-PA-10003641 | P5280: Office Supplies | Q5280: Paper | R5280: Xerox 1909 | S5280: 105.52 | T5280: 4 | U5280: 0 | V5280: 48.5392
A5281: 5280 | B5281: US-2014-104094 | C5281: =YEAR(Data!$D5281) -> 2014 | D5281: 41890 | E5281: 41894 | F5281: Standard Class | G5281: AG-10675 | H5281: Anna Gayman | I5281: Consumer | J5281: United States | K5281: Milwaukee | L5281: Wisconsin | M5281: 53209 | N5281: Central | O5281: TEC-AC-10002134 | P5281: Technology | Q5281: Accessories | R5281: Rosewill 107 Normal Keys USB Wired Standard Keyboard | S5281: 13.48 | T5281: 1 | U5281: 0 | V5281: 1.8872
A5282: 5281 | B5282: CA-2014-152709 | C5282: =YEAR(Data!$D5282) -> 2014 | D5282: 41920 | E5282: 41925 | F5282: Standard Class | G5282: DB-13210 | H5282: Dean Braden | I5282: Consumer | J5282: United States | K5282: Detroit | L5282: Michigan | M5282: 48234 | N5282: Central | O5282: OFF-ST-10001837 | P5282: Office Supplies | Q5282: Storage | R5282: SAFCO Mobile Desk Side File, Wire Frame | S5282: 85.52 | T5282: 2 | U5282: 0 | V5282: 22.2352
A5283: 5282 | B5283: CA-2012-105158 | C5283: =YEAR(Data!$D5283) -> 2012 | D5283: 41157 | E5283: 41162 | F5283: Standard Class | G5283: SP-20860 | H5283: Sung Pak | I5283: Corporate | J5283: United States | K5283: Rochester | L5283: Minnesota | M5283: 55901 | N5283: Central | O5283: FUR-FU-10001706 | P5283: Furniture | Q5283: Furnishings | R5283: Longer-Life Soft White Bulbs | S5283: 6.16 | T5283: 2 | U5283: 0 | V5283: 2.9568
A5284: 5283 | B5284: CA-2012-105158 | C5284: =YEAR(Data!$D5284) -> 2012 | D5284: 41157 | E5284: 41162 | F5284: Standard Class | G5284: SP-20860 | H5284: Sung Pak | I5284: Corporate | J5284: United States | K5284: Rochester | L5284: Minnesota | M5284: 55901 | N5284: Central | O5284: OFF-PA-10001970 | P5284: Office Supplies | Q5284: Paper | R5284: Xerox 1881 | S5284: 36.84 | T5284: 3 | U5284: 0 | V5284: 17.3148
A5285: 5284 | B5285: CA-2011-133424 | C5285: =YEAR(Data!$D5285) -> 2011 | D5285: 40632 | E5285: 40637 | F5285: Standard Class | G5285: Dl-13600 | H5285: Dorris liebe | I5285: Corporate | J5285: United States | K5285: Seattle | L5285: Washington | M5285: 98105 | N5285: West | O5285: OFF-ST-10002957 | P5285: Office Supplies | Q5285: Storage | R5285: Sterilite Show Offs Storage Containers | S5285: 15.84 | T5285: 3 | U5285: 0 | V5285: 0
A5286: 5285 | B5286: CA-2011-133424 | C5286: =YEAR(Data!$D5286) -> 2011 | D5286: 40632 | E5286: 40637 | F5286: Standard Class | G5286: Dl-13600 | H5286: Dorris liebe | I5286: Corporate | J5286: United States | K5286: Seattle | L5286: Washington | M5286: 98105 | N5286: West | O5286: OFF-LA-10002312 | P5286: Office Supplies | Q5286: Labels | R5286: Avery 490 | S5286: 44.4 | T5286: 3 | U5286: 0 | V5286: 22.2
A5287: 5286 | B5287: CA-2014-105991 | C5287: =YEAR(Data!$D5287) -> 2014 | D5287: 41765 | E5287: 41766 | F5287: First Class | G5287: LH-17020 | H5287: Lisa Hazard | I5287: Consumer | J5287: United States | K5287: Louisville | L5287: Colorado | M5287: 80027 | N5287: West | O5287: OFF-EN-10002600 | P5287: Office Supplies | Q5287: Envelopes | R5287: Redi-Strip #10 Envelopes, 4 1/8 x 9 1/2 | S5287: 21.24 | T5287: 9 | U5287: 0.2 | V5287: 7.434
...

Sheet layout
A11: `` | B11: =#REF! -> #REF!
